<?xml version="1.0" encoding="UTF-8"?>
<robot xmlns:xacro="http://www.ros.org/wiki/xacro">

  <xacro:macro name="RSP" params="name parent">
    
    <link name="${name}_palm">
      <visual>
      	<origin xyz="0 0 0.05"  rpy="0 0 0"/>
      	
        <geometry>
      	  <box size="0.4 0.15 0.1"/>
      	</geometry>
      	
        <material name="yellow">
      	  <color rgba="0.8 0.8 0.8 1.0"/>
      	</material>
      
      </visual>
    </link>
    
    <link name="${name}_left_finger">
      <visual>
      	<origin xyz="0 0 0.15"  rpy="0 0 0"/>
      	
        <geometry>
      	  <box size="0.1 0.15 0.3"/>
      	</geometry>
      	
        <material name="gray">
      	  <color rgba="0.7 0.7 0.7 1.0"/>
      	</material>
      
      </visual>
    </link>
    
    <link name="${name}_right_finger">
      <visual>
        <origin xyz="0 0 0.15" rpy="0 0 0"/>
        
        <geometry>
          <box size="0.1 0.15 0.3"/>
        </geometry> 
        
        <material name="gray">
          <color rgba="0.7 0.7 0.7 1.0"/>
        </material>
      
      </visual>
    </link>
    
    <link name="${name}_pick">
      
    </link>

    <joint name="${name}_palm_joint" type="fixed">
      <parent link="${parent}"/>
      <child link="${name}_palm"/>
    </joint>

    <joint name="${name}_joint" type="prismatic">
      <parent link="${name}_palm"/>
      <child link="${name}_left_finger"/>
      <origin xyz="0.15 0 0" rpy="0 0 0"/>
      <axis xyz="1 0 0"/>
      <limit effort="30" velocity="0.1" lower="-0.15" upper="0"/>
    </joint> 

    <joint name="${name}_joint_2" type="prismatic">
      <parent link="${name}_palm"/>
      <child link="${name}_right_finger"/>
      <mimic joint="${name}_joint" multiplier="-1"  offset = "0"/>
      <origin xyz="-0.15 0 0" rpy="0 0 0"/>
      <axis xyz="1 0 0"/>
      <limit effort="30" velocity="0.1" lower="-0.15" upper="0"/>
    </joint> 

    <joint name="${name}_pick" type="fixed">
      <parent link="${name}_palm"/>
      <child link="${name}_pick"/>
      <origin xyz="0.0 0.0 0.3"/>
    </joint>
    
  </xacro:macro>
  
</robot>
