<?xml version="1.0" encoding="UTF-8"?>
<robot xmlns:xacro="http://www.ros.org/wiki/xacro">

  <xacro:macro name="RSP" params="name parent">
    
    <link name="${name}_link_0">
      <visual>
      	<origin xyz="0 0 0.25"  rpy="0 0 0"/>
      	
        <geometry>
      	  <box size="0.5 0.5 0.5"/>
      	</geometry>
      	
        <material name="yellow">
      	  <color rgba="0.8 0.8 0.0 1.0"/>
      	</material>
      
      </visual>
    </link>
    
    <link name="${name}_link_1">
      <visual>
      	<origin xyz="0 0 0.25"  rpy="0 0 0"/>
      	
        <geometry>
      	  <cylinder length="0.5" radius="0.1"/>
      	</geometry>
      	
        <material name="black">
      	  <color rgba="0.0 0.0 0.0 1.0"/>
      	</material>
      
      </visual>
    </link>
    
    <link name="${name}_link_2">
      <visual>
        <origin xyz="0 0 0.25" rpy="0 0 0"/>
        
        <geometry>
          <cylinder length="0.5" radius="0.1"/>
        </geometry> 
        
        <material name="black">
          <color rgba="0.0 0.0 0.0 1.0"/>
        </material>
      
      </visual>
    </link>
    
    <link name="${name}_flange">
      
    </link>

    <joint name="${name}_base_joint" type="fixed">
      <parent link="${parent}"/>
      <child link="${name}_link_0"/>
    </joint>

    <joint name="${name}_joint_1" type="revolute">
      <parent link="${name}_link_0"/>
      <child link="${name}_link_1"/>
      <origin xyz="0 0 0.5" rpy="0 0 0"/>
      <axis xyz="0 0 1"/>
      <limit lower="-1" upper="1.0" effort="10.0" velocity="1.0"/>
    </joint>
    
    <joint name="${name}_joint_2" type="revolute">
      <parent link="${name}_link_1"/>
      <child link="${name}_link_2"/>
      <origin xyz="0 0 0.5" rpy="1.57 0 0"/>
      <limit lower="-1" upper="1.0" effort="10.0" velocity="1.0"/>
    </joint>

    <joint name="${name}_joint_tip" type="fixed">
      <parent link="${name}_link_2"/>
      <child link="${name}_flange"/>
      <origin xyz="0.0 0.0 0.5"/>
    </joint>
    
  </xacro:macro>
  
</robot>
