<?xml version="1.0" ?>
<!-- =================================================================================== -->
<!-- |    This document was autogenerated by xacro from robot.urdf.xacro               | -->
<!-- |    EDITING THIS FILE BY HAND IS NOT RECOMMENDED                                 | -->
<!-- =================================================================================== -->
<robot name="RSP">
  <link name="world"/>
  <link name="arm_link_0">
    <visual>
      <origin xyz="0 0 0"/>
      <geometry>
        <box size="0.5 0.5 0.5"/>
      </geometry>
      <material name="blue">
        <color rgba="0.0 0.0 0.8 1.0"/>
      </material>
    </visual>
  </link>
  <link name="arm_link_1">
    <visual>
      <origin xyz="0 0 0.5"/>
      <geometry>
        <cylinder length="0.5" radius="0.2"/>
      </geometry>
      <material name="white">
        <color rgba="0.8 0.8 0.8 1.0"/>
      </material>
    </visual>
  </link>
  <link name="arm_link_2">
    <visual>
      <origin rpy="1.5707963267948966 0 0" xyz="0 0 0.5"/>
      <geometry>
        <cylinder length="0.5" radius="0.2"/>
      </geometry>
      <material name="white">
        <color rgba="0.8 0.8 0.8 1.0"/>
      </material>
    </visual>
  </link>
  <link name="arm_flange">
      
    </link>
  <joint name="arm_base_joint" type="fixed">
    <parent link="world"/>
    <child link="arm_link_0"/>
  </joint>
  <joint name="arm_joint_1" type="revolute">
    <parent link="arm_link_0"/>
    <child link="arm_link_1"/>
    <origin rpy="0 0 0" xyz="0 0 0.5"/>
    <!-- <limit lower="-1" upper="1" effort="10" velocity="1"/> -->
  </joint>
  <joint name="arm_joint_2" type="revolute">
    <parent link="arm_link_1"/>
    <child link="arm_link_2"/>
    <origin rpy="1.5707963267948966 0 0" xyz="0 0 0.5"/>
  </joint>
  <joint name="arm_joint_tip" type="fixed">
    <parent link="arm_link_2"/>
    <child link="arm_flange"/>
    <origin xyz="0.0 0.0 0.5"/>
  </joint>
</robot>
